<?xml version="1.0" encoding="utf-8"?>
<!-- This URDF was automatically created by SolidWorks to URDF Exporter! Originally created by Stephen Brawner (brawner@gmail.com) 
     Commit Version: 1.5.0-0-g9aa0fdb  Build Version: 1.5.7004.21443
     For more information, please see http://wiki.ros.org/sw_urdf_exporter -->
<robot
  name="UtahBody.SLDASM">
  <link
    convex="yes"
    name="base_link">
    <inertial>
      <origin
        xyz="0.00122383806382909 -3.17942980033395E-17 0.0659595203814596"
        rpy="0 0 0" />
      <mass
        value="24.9329927506" />
      <inertia
        ixx="5.55262025860006"
        ixy="8.98835590924511E-16"
        ixz="-0.000394714970341267"
        iyy="5.44179501990665"
        iyz="-2.98538962318851E-16"
        izz="10.2631638380994" />
    </inertial>
    <visual>
      <origin
        xyz="0 0 0"
        rpy="0 0 0" />
      <geometry>
        <mesh
          filename="UtahBody.SLDASM/meshes/base_link.STL" />
      </geometry>
      <material
        name="">
        <color
          rgba="1 1 1 1" />
      </material>
    </visual>
    <collision>
      <origin
        xyz="0 0 0"
        rpy="0 0 0" />
      <geometry>
        <mesh
          filename="UtahBody.SLDASM/meshes/base_link.STL" />
      </geometry>
    </collision>
  </link>
  <link
    convex="yes"
    name="Femur_L">
    <inertial>
      <origin
        xyz="0.242203107830059 -0.00284577498225344 0.0924919582228952"
        rpy="0 0 0" />
      <mass
        value="1.0956267569314" />
      <inertia
        ixx="0.000770809917908148"
        ixy="0.000413272308722677"
        ixz="-0.00199415247363703"
        iyy="0.0359395923546767"
        iyz="2.34305677777084E-05"
        izz="0.0354701341892382" />
    </inertial>
    <visual>
      <origin
        xyz="0 0 0"
        rpy="0 0 0" />
      <geometry>
        <mesh
          filename="UtahBody.SLDASM/meshes/Femur_L.STL" />
      </geometry>
      <material
        name="">
        <color
          rgba="0.00784313725490196 0.23921568627451 0.823529411764706 1" />
      </material>
    </visual>
    <collision>
      <origin
        xyz="0 0 0"
        rpy="0 0 0" />
      <geometry>
        <mesh
          filename="UtahBody.SLDASM/meshes/Femur_L.STL" />
      </geometry>
    </collision>
  </link>
  <joint
    name="Hip_femur_L"
    type="continuous">
    <origin
      xyz="-0.0385868696304645 0.18 0.0672852031451373"
      rpy="-1.5707963267949 1.50458688118117 0" />
    <parent
      link="base_link" />
    <child
      link="Femur_L" />
    <axis
      xyz="0 0 1" />
    <limit effort="300" velocity="0.17453292519943295" />
    <safety_controller
      k_velocity="0" />
  </joint>
  <link
    convex="yes"
    name="Tibia_L">
    <inertial>
      <origin
        xyz="0.261668636750511 -0.00305413840682148 -0.023999999127617"
        rpy="0 0 0" />
      <mass
        value="0.837833351696081" />
      <inertia
        ixx="0.000224729291285804"
        ixy="0.000203159080373753"
        ixz="8.62500209497016E-10"
        iyy="0.0175133040900648"
        iyz="1.47446822069347E-11"
        izz="0.0175171715862385" />
    </inertial>
    <visual>
      <origin
        xyz="0 0 0"
        rpy="0 0 0" />
      <geometry>
        <mesh
          filename="UtahBody.SLDASM/meshes/Tibia_L.STL" />
      </geometry>
      <material
        name="">
        <color
          rgba="0.00784313725490196 0.23921568627451 0.823529411764706 1" />
      </material>
    </visual>
    <collision>
      <origin
        xyz="0 0 0"
        rpy="0 0 0" />
      <geometry>
        <mesh
          filename="UtahBody.SLDASM/meshes/Tibia_L.STL" />
      </geometry>
    </collision>
  </link>
  <joint
    name="Femur_tibia_L"
    type="continuous">
    <origin
      xyz="0.557961346760059 -0.00655865516646524 0.0770000001743604"
      rpy="0 0 -0.00193315362723463" />
    <parent
      link="Femur_L" />
    <child
      link="Tibia_L" />
    <axis
      xyz="0 0 -1" />
    <limit effort="300" velocity="0.17453292519943295" />
    <safety_controller
      k_velocity="0" />
  </joint>
  <link
    convex="yes"
    name="Tarsa_L">
    <inertial>
      <origin
        xyz="0.0302857093798252 -0.00810522006820646 0.070000040207787"
        rpy="0 0 0" />
      <mass
        value="0.1015318884241" />
      <inertia
        ixx="2.83277886698444E-05"
        ixy="2.1601549548652E-07"
        ixz="6.83242656182688E-12"
        iyy="4.67036221075615E-05"
        iyz="6.0767724694821E-12"
        izz="4.96436344707768E-05" />
    </inertial>
    <visual>
      <origin
        xyz="0 0 0"
        rpy="0 0 0" />
      <geometry>
        <mesh
          filename="UtahBody.SLDASM/meshes/Tarsa_L.STL" />
      </geometry>
      <material
        name="">
        <color
          rgba="0.00784313725490196 0.23921568627451 0.823529411764706 1" />
      </material>
    </visual>
    <collision>
      <origin
        xyz="0 0 0"
        rpy="0 0 0" />
      <geometry>
        <mesh
          filename="UtahBody.SLDASM/meshes/Tarsa_L.STL" />
      </geometry>
    </collision>
  </link>
  <joint
    name="Tibia_tarsa_L"
    type="continuous">
    <origin
      xyz="0.507031720085334 -0.00595264631811062 -0.0469999948873179"
      rpy="0 0 2.35013161415813" />
    <parent
      link="Tibia_L" />
    <child
      link="Tarsa_L" />
    <axis
      xyz="0 0 -1" />
    <limit effort="300" velocity="0.17453292519943295" />
    <safety_controller
      k_velocity="0" />
  </joint>
  <link
    convex="yes"
    name="Foot_L">
    <inertial>
      <origin
        xyz="-0.134046955227231 -0.0400232687764869 -0.149551845220791"
        rpy="0 0 0" />
      <mass
        value="10.834771497095713" />
      <inertia
        ixx="0.00329402342120859"
        ixy="-0.00225499866549155"
        ixz="4.00642092161077E-10"
        iyy="0.0132217193918293"
        iyz="2.89352007714829E-10"
        izz="0.0109505994990665" />
    </inertial>
    <visual>
      <origin
        xyz="0 0 0"
        rpy="0 0 0" />
      <geometry>
        <mesh
          filename="UtahBody.SLDASM/meshes/Foot_L.STL" />
      </geometry>
      <material
        name="">
        <color
          rgba="0.00784313725490196 0.23921568627451 0.823529411764706 1" />
      </material>
    </visual>
    <collision>
      <origin
        xyz="0 0 0"
        rpy="0 0 0" />
      <geometry>
        <mesh
          filename="UtahBody.SLDASM/meshes/Foot_L.STL" />
      </geometry>
    </collision>
  </link>
  <joint
    name="Tarsa_foot_L"
    type="continuous">
    <origin
      xyz="0.0545835119848165 -0.00841169146295107 0.0929999850227678"
      rpy="0 0 -0.0126879406929578" />
    <parent
      link="Tarsa_L" />
    <child
      link="Foot_L" />
    <axis
      xyz="0 0 0.999999999999996" />
    <limit effort="300" velocity="0.17453292519943295" />
    <safety_controller
      k_velocity="0" />
  </joint>
  <link
    convex="yes"
    name="Femur_R">
    <inertial>
      <origin
        xyz="0.242203107594868 -0.00284577821776226 -0.0924919582317857"
        rpy="0 0 0" />
      <mass
        value="1.09562675424786" />
      <inertia
        ixx="0.000770809907869585"
        ixy="0.000413271827180529"
        ixz="0.00199415248143469"
        iyy="0.0359395923291157"
        iyz="-2.34302735430893E-05"
        izz="0.0354701341468065" />
    </inertial>
    <visual>
      <origin
        xyz="0 0 0"
        rpy="0 0 0" />
      <geometry>
        <mesh
          filename="UtahBody.SLDASM/meshes/Femur_R.STL" />
      </geometry>
      <material
        name="">
        <color
          rgba="0.00784313725490196 0.23921568627451 0.823529411764706 1" />
      </material>
    </visual>
    <collision>
      <origin
        xyz="0 0 0"
        rpy="0 0 0" />
      <geometry>
        <mesh
          filename="UtahBody.SLDASM/meshes/Femur_R.STL" />
      </geometry>
    </collision>
  </link>
  <joint
    name="Hips_femur_R"
    type="continuous">
    <origin
      xyz="-0.0385868696304645 -0.18 0.0672852031451373"
      rpy="-1.5707963267949 1.50458688118117 0" />
    <parent
      link="base_link" />
    <child
      link="Femur_R" />
    <axis
      xyz="0 0 1" />
    <limit effort="300" velocity="0.17453292519943295" />
    <safety_controller
      k_velocity="0" />
  </joint>
  <link
    convex="yes"
    name="Tibia_R">
    <inertial>
      <origin
        xyz="0.261668641621138 -0.00305415187488046 0.0239999993678786"
        rpy="0 0 0" />
      <mass
        value="0.837833381982962" />
      <inertia
        ixx="0.000224729299568724"
        ixy="0.000203161324382621"
        ixz="-9.62315070088139E-10"
        iyy="0.0175133046826421"
        iyz="6.79629889809555E-11"
        izz="0.0175171721226335" />
    </inertial>
    <visual>
      <origin
        xyz="0 0 0"
        rpy="0 0 0" />
      <geometry>
        <mesh
          filename="UtahBody.SLDASM/meshes/Tibia_R.STL" />
      </geometry>
      <material
        name="">
        <color
          rgba="0.00784313725490196 0.23921568627451 0.823529411764706 1" />
      </material>
    </visual>
    <collision>
      <origin
        xyz="0 0 0"
        rpy="0 0 0" />
      <geometry>
        <mesh
          filename="UtahBody.SLDASM/meshes/Tibia_R.STL" />
      </geometry>
    </collision>
  </link>
  <joint
    name="Femur_tibia_R"
    type="continuous">
    <origin
      xyz="0.557961346760059 -0.00655865516646524 -0.0770000001743603"
      rpy="0 0 -0.00193315362723463" />
    <parent
      link="Femur_R" />
    <child
      link="Tibia_R" />
    <axis
      xyz="0 0 1" />
    <limit effort="300" velocity="0.17453292519943295" />
    <safety_controller
      k_velocity="0" />
  </joint>
  <link
    convex="yes"
    name="Tarsa_R">
    <inertial>
      <origin
        xyz="0.0302857093798253 -0.00810522006820635 -0.0700000402077869"
        rpy="0 0 0" />
      <mass
        value="0.1015318884241" />
      <inertia
        ixx="2.83277886698443E-05"
        ixy="2.16015495486542E-07"
        ixz="-6.8324266014177E-12"
        iyy="4.67036221075615E-05"
        iyz="-6.07677249578629E-12"
        izz="4.96436344707768E-05" />
    </inertial>
    <visual>
      <origin
        xyz="0 0 0"
        rpy="0 0 0" />
      <geometry>
        <mesh
          filename="UtahBody.SLDASM/meshes/Tarsa_R.STL" />
      </geometry>
      <material
        name="">
        <color
          rgba="0.00784313725490196 0.23921568627451 0.823529411764706 1" />
      </material>
    </visual>
    <collision>
      <origin
        xyz="0 0 0"
        rpy="0 0 0" />
      <geometry>
        <mesh
          filename="UtahBody.SLDASM/meshes/Tarsa_R.STL" />
      </geometry>
    </collision>
  </link>
  <joint
    name="Tibia_tarsa_R"
    type="continuous">
    <origin
      xyz="0.507031720085334 -0.00595264631811062 0.0469999948873179"
      rpy="0 0 2.35013161415813" />
    <parent
      link="Tibia_R" />
    <child
      link="Tarsa_R" />
    <axis
      xyz="0 0 1" />
    <limit effort="300" velocity="0.17453292519943295" />
    <safety_controller
      k_velocity="0" />
  </joint>
  <link
    convex="yes"
    name="Foot_R">
    <inertial>
      <origin
        xyz="-0.134046955227231 -0.0400232687764868 0.149551845220791"
        rpy="0 0 0" />
      <mass
        value="10.834771497095712" />
      <inertia
        ixx="0.00329402342120859"
        ixy="-0.00225499866549155"
        ixz="-4.00642091881399E-10"
        iyy="0.0132217193918293"
        iyz="-2.89352008316691E-10"
        izz="0.0109505994990664" />
    </inertial>
    <visual>
      <origin
        xyz="0 0 0"
        rpy="0 0 0" />
      <geometry>
        <mesh
          filename="UtahBody.SLDASM/meshes/Foot_R.STL" />
      </geometry>
      <material
        name="">
        <color
          rgba="0.00784313725490196 0.23921568627451 0.823529411764706 1" />
      </material>
    </visual>
    <collision>
      <origin
        xyz="0 0 0"
        rpy="0 0 0" />
      <geometry>
        <mesh
          filename="UtahBody.SLDASM/meshes/Foot_R.STL" />
      </geometry>
    </collision>
  </link>
  <joint
    name="Tarsa_foot_R"
    type="continuous">
    <origin
      xyz="0.0545835119848167 -0.00841169146295095 -0.0929999850227678"
      rpy="0 0 -0.0126879406929579" />
    <parent
      link="Tarsa_R" />
    <child
      link="Foot_R" />
    <axis
      xyz="0 0 -0.999999999999996" />
    <limit effort="300" velocity="0.17453292519943295" />
    <safety_controller
      k_velocity="0" />
  </joint>
  <link
    name="Tail">
    <inertial>
      <origin
        xyz="0.421457332725084 -9.67276904467562E-10 -0.0568211726179445"
        rpy="0 0 0" />
      <mass
        value="2.43669066002775" />
      <inertia
        ixx="0.00361500190357776"
        ixy="-7.00435857004311E-10"
        ixz="0.00346870361655754"
        iyy="0.102575187379763"
        iyz="1.22087694850174E-10"
        izz="0.102066233974879" />
    </inertial>
    <visual>
      <origin
        xyz="0 0 0"
        rpy="0 0 0" />
      <geometry>
        <mesh
          filename="BodyWithTail/meshes/Tail.STL" />
      </geometry>
      <material
        name="">
        <color
          rgba="0.00784313725490196 0.23921568627451 0.823529411764706 1" />
      </material>
    </visual>
    <collision>
      <origin
        xyz="0 0 0"
        rpy="0 0 0" />
      <geometry>
        <mesh
          filename="BodyWithTail/meshes/Tail.STL" />
      </geometry>
    </collision>
  </link>
  <joint
    name="Hips_Tail"
    type="continuous">
    <origin
      xyz="-0.193717960242815 0 0.132"
      rpy="3.14159265358979 0 3.14159265358979" />
    <parent
      link="base_link" />
    <child
      link="Tail" />
    <axis
      xyz="0 0 1" />
    <limit effort="300" velocity="0.17453292519943295" />
    <safety_controller
      k_velocity="0" />
  </joint>
</robot>